Workbook
Name beta: 'DCF Valuation'!$C$20
Name company: Cover!$C$2
Name costofdebt: 'DCF Valuation'!$C$22
Name currentprice: Cover!$C$4
Name dilutedshares: Comparables!$C$7
Name dilutedshares: #REF!
Name equityvalue: Comparables!$C$8
Name equityvalue: #REF!
Name ev: Comparables!$C$12
Name ev: #REF!
Name mrp: 'DCF Valuation'!$C$19
Name netdebt: Comparables!$C$10
Name netdebt: #REF!
Name rd: 'DCF Valuation'!$C$24
Name re: 'DCF Valuation'!$C$21
Name rf: 'DCF Valuation'!$C$18
Name rm: 'DCF Valuation'!$C$17
Name taxrate: 'DCF Valuation'!$C$23
Name tgr: 'DCF Valuation'!$D$48
Name wacc: 'DCF Valuation'!$C$25

Sheet Cover
B2: Company | C2: lululemon athletica inc.
B3: Ticker | C3: NASDAQ: LULU
B4: Price | C4: 212.54
B5: Team Number
B7: =company&" – Financial Model" -> lululemon athletica inc. – Financial Model
B15: Sauder Capital Markets Challenge
C16: First Round Case
B17: =TODAY() -> 46022
B19: Case Sponsor
B27: Gold Sponsor
B29: Board of Directors

Sheet Instructions
B1: Sauder Capital Markets Challenge
B2: =company -> lululemon athletica inc.
B3: Financial Model
B4: Instructions
B6: General Instructions
B8: 1 | C8: Follow the color and formatting guide below
B9: =B8+1 -> 2 | C9: Keep all financial statements on an annual basis
B10: =B9+1 -> 3 | C10: All figures should be in $USDm unless otherwise specified
B11: =B10+1 -> 4 | C11: Do not overwrite formulas on the existing model. Add new lines only.
B12: =B11+1 -> 5 | C12: Keep all schedules in the "Supporting Schedules" tab
B13: =B12+1 -> 6 | C13: Do not delete or add any tabs
B14: =B13+1 -> 7 | C14: Teams are permitted to use Generative AI to learn concepts; other uses must be disclosed in the pitch deck as references
B17: DCF Valuation Instructions
B19: 1 | C19: Pull the company's historical financials from its filings or a data provider
B20: =B19+1 -> 2 | C20: Map the figures into the Financial Statements tab and use the same name lines as the template
B21: =B20+1 -> 3 | C21: Add or remove detail by inserting new rows while keeping the final subtotals aligned
B22: =B21+1 -> 4 | C22: Ensure all new rows link correctly to the relevant totals
B23: =B22+1 -> 5 | C23: If historical numbers require reclassification, adjust them so that revenue, COGS, operating costs, depreciation, taxes, working capital, capital spending, and interest items align with the structure given
B24: =B23+1 -> 6 | C24: Forecast revenue, margins, operating costs, depreciation, interest, taxes, and any other required items
B25: =B24+1 -> 7 | C25: Keep formulas in black for any pattern that repeats across multiple periods
B26: =B25+1 -> 8 | C26: Create supporting schedules to drive items in the cash flow statement and tie them into the balance sheet; suggested schedules are in the Supporting Schedules tab
B27: =B26+1 -> 9 | C27: Go to the DCF valuation tab and link free cash flow from the statements
B28: =B27+1 -> 10 | C28: Compute the present value of each free cash flow year in black
B29: =B28+1 -> 11 | C29: Enter WACC inputs, terminal growth, and other assumptions in blue in the yellow input box
B30: =B29+1 -> 12 | C30: Confirm that the model produces a final implied share price and implied upside
B31: =B30+1 -> 13 | C31: Optional: add charts, summary tables, and additional outputs for presentation use
B34: Comparable & Precedent Transaction Valuation Instructions
B36: 1 | C36: Select comparable companies and precedent transactions
B37: =B36+1 -> 2 | C37: Include rationale briefly in far right column for the precedent transactions
B38: =B37+1 -> 3 | C38: Populate cells with comparable companies' relevant data points
B39: =B38+1 -> 4 | C39: Populate cells with precedent transactions relevant deal multiples
B40: =B39+1 -> 5 | C40: Fill out target company's relevant financial data points
B41: =B40+1 -> 6 | C41: Upon all fields being completed, an implied transaction value will populate
B44: Formatting Guides
B46: Color Formatting Guide
B48: Color | C48: Description | D48: Hex Code
B49: Blue | C49: Hardcoded values | D49: #0000FF
B50: Black | C50: Formulas; calculated values | D50: #000000
B51: Green | C51: Reference within sheet | D51: #009B00
B52: Red | C52: Reference to another sheet | D52: #FF0000
...

Sheet Financial Statements
B1: Sauder Capital Markets Challenge
B2: Lululemon (NASDAQ: LULU)
B3: Financial Model
B4: Financial Statements
B6: Years | C6: 2020 | D6: =C6+1 -> 2021 | E6: =D6+1 -> 2022 | F6: =E6+1 -> 2023 | G6: =F6+1 -> 2024 | H6: =G6+1 -> 2025 | I6: =H6+1 -> 2026 | J6: =I6+1 -> 2027 | K6: =J6+1 -> 2028 | ... Q6: =P6+1 -> 2034
B7: For the year ended | C7: =EOMONTH(D7,-12) -> 44227 | D7: 44591 | E7: 44955 | F7: 45319 | G7: 45690 | H7: =EOMONTH(G7,11) -> 46053 | I7: =EOMONTH(H7,12) -> 46418 | J7: =EOMONTH(I7,12) -> 46783 | K7: =EOMONTH(J7,12) -> 47149 | L7: =EOMONTH(K7,12) -> 47514 | M7: =EOMONTH(L7,12) -> 47879 | N7: =EOMONTH(M7,12) -> 48244 | O7: =EOMONTH(N7,12) -> 48610 | P7: =EOMONTH(O7,12) -> 48975 | Q7: =EOMONTH(P7,12) -> 49340
B8: Income Statement
B10: Revenue | C10: 4401.879 | D10: 6256.617 | E10: 8110.518 | F10: 9619.278 | G10: 10588.126 | H10: ='Revenue Build Schedule'!G20 -> 11953.361 | I10: ='Revenue Build Schedule'!H20 -> 13466.421 | J10: ='Revenue Build Schedule'!I20 -> 14882.823 | K10: ='Revenue Build Schedule'!J20 -> 16156.499 | L10: ='Revenue Build Schedule'!K20 -> 17251.592 | M10: ='Revenue Build Schedule'!L20 -> 18144.884 | N10: ='Revenue Build Schedule'!M20 -> 18826.774 | O10: ='Revenue Build Schedule'!N20 -> 19300.838 | ... Q10: ='Revenue Build Schedule'!P20 -> 19695.44
B11: Revenue Growth % | C11: =IFERROR(C10/B10-1," ") | D11: =IFERROR(D10/C10-1," ") -> 0.42135143 | E11: =IFERROR(E10/D10-1," ") -> 0.29631045 | F11: =IFERROR(F10/E10-1," ") -> 0.18602511 | G11: =IFERROR(G10/F10-1," ") -> 0.10071941 | H11: =IFERROR(H10/G10-1," ") -> 0.1289402 | I11: =IFERROR(I10/H10-1," ") -> 0.12658029 | J11: =IFERROR(J10/I10-1," ") -> 0.10518029 | ... Q11: =IFERROR(Q10/P10-1," ") -> 0.0057802888
B12: Cost of Goods Sold | C12: -1937.888 | D12: -2648.052 | E12: -3618.178 | F12: -4009.873 | G12: -4317.315 | H12: ='Supporting Schedules'!I11 -> -4876.9713 | I12: ='Supporting Schedules'!J11 -> -5413.5012 | J12: ='Supporting Schedules'!K11 -> -5923.3636 | K12: ='Supporting Schedules'!L11 -> -6397.9737 | L12: ='Supporting Schedules'!M11 -> -6797.1271 | M12: ='Supporting Schedules'!N11 -> -7112.7945 | N12: ='Supporting Schedules'!O11 -> -7380.0954 | O12: ='Supporting Schedules'!P11 -> -7565.9283 | ... Q12: ='Supporting Schedules'!R11 -> -7720.6126
B13: COGS Margin % | C13: =IFERROR(-C12/C10," ") -> 0.44024109 | D13: =IFERROR(-D12/D10," ") -> 0.42324023 | E13: =IFERROR(-E12/E10," ") -> 0.44610936 | F13: =IFERROR(-F12/F10," ") -> 0.416858 | G13: =IFERROR(-G12/G10," ") -> 0.40775063 | H13: =IFERROR(-H12/H10," ") -> 0.408 | I13: =IFERROR(-I12/I10," ") -> 0.402 | J13: =IFERROR(-J12/J10," ") -> 0.398 | ... Q13: =IFERROR(-Q12/Q10," ") -> 0.392
B14: Equals: Gross Profit | C14: =SUM(C10,C12) -> 2463.991 | D14: =SUM(D10,D12) -> 3608.565 | E14: =SUM(E10,E12) -> 4492.34 | F14: =SUM(F10,F12) -> 5609.405 | G14: =SUM(G10,G12) -> 6270.811 | H14: =SUM(H10,H12) -> 7076.3898 | I14: =SUM(I10,I12) -> 8052.9198 | J14: =SUM(J10,J12) -> 8959.4595 | ... Q14: =SUM(Q10,Q12) -> 11974.828
B15: Gross Profit % | C15: =IFERROR(C14/C10," ") -> 0.55975891 | D15: =IFERROR(D14/D10," ") -> 0.57675977 | E15: =IFERROR(E14/E10," ") -> 0.55389064 | F15: =IFERROR(F14/F10," ") -> 0.583142 | G15: =IFERROR(G14/G10," ") -> 0.59224937 | H15: =IFERROR(H14/H10," ") -> 0.592 | I15: =IFERROR(I14/I10," ") -> 0.598 | J15: =IFERROR(J14/J10," ") -> 0.602 | ... Q15: =IFERROR(Q14/Q10," ") -> 0.608
B17: Operating Expenses
B18: Selling, General & Administrative | C18: -1609.003 | D18: -2225.034 | E18: -2757.447 | F18: -3397.218 | G18: -3762.379 | H18: ='Supporting Schedules'!I18 -> -5047.0534 | I18: ='Supporting Schedules'!J18 -> -5766.3632 | J18: ='Supporting Schedules'!K18 -> -6432.1146 | K18: ='Supporting Schedules'!L18 -> -7014.6557 | L18: ='Supporting Schedules'!M18 -> -7524.4289 | M18: ='Supporting Schedules'!N18 -> -7950.1942 | N18: ='Supporting Schedules'!O18 -> -8248.862 | O18: ='Supporting Schedules'!P18 -> -8456.5018 | ... Q18: ='Supporting Schedules'!R18 -> -8629.3379
B19: Impairment of goodwill and other assets, restructuring costs | C19: 0 | D19: 0 | E19: -407.913 | F19: -74.501 | G19: 0 | H19: =G19 -> 0 | I19: =H19 -> 0 | J19: =I19 -> 0 | K19: =J19 -> 0 | L19: =K19 -> 0 | M19: =L19 -> 0 | N19: =M19 -> 0 | O19: =N19 -> 0 | ... Q19: =P19 -> 0
B20: Amortization of intangible assets | C20: -5.16 | D20: -8.782 | E20: -8.752 | F20: -5.01 | G20: -2.735 | H20: =G20*(1+H11) -> -3.0876515 | I20: =H20*(1+I11) -> -3.4784873 | J20: =I20*(1+J11) -> -3.8443556 | K20: =J20*(1+K11) -> -4.1733566 | L20: =K20*(1+L11) -> -4.4562279 | M20: =L20*(1+M11) -> -4.6869727 | N20: =M20*(1+N11) -> -4.8631105 | O20: =N20*(1+O11) -> -4.985565 | ... Q20: =P20*(1+Q11) -> -5.0874942
B21: Acquisition-related expenses | C21: -29.842 | D21: -41.394 | E21: 0 | F21: 0 | G21: 0 | H21: =G21 -> 0 | I21: =H21 -> 0 | J21: =I21 -> 0 | K21: =J21 -> 0 | L21: =K21 -> 0 | M21: =L21 -> 0 | N21: =M21 -> 0 | O21: =N21 -> 0 | ... Q21: =P21 -> 0
B22: Gain on disposal of assets | C22: 0 | D22: 0 | E22: 10.18 | F22: 0 | G22: 0 | H22: =G22 -> 0 | I22: =H22 -> 0 | J22: =I22 -> 0 | K22: =J22 -> 0 | L22: =K22 -> 0 | M22: =L22 -> 0 | N22: =M22 -> 0 | O22: =N22 -> 0 | ... Q22: =P22 -> 0
B23: Total Operating Expenses | C23: =SUM(C18:C22) -> -1644.005 | D23: =SUM(D18:D22) -> -2275.21 | E23: =SUM(E18:E22) -> -3163.932 | F23: =SUM(F18:F22) -> -3476.729 | G23: =SUM(G18:G22) -> -3765.114 | H23: =SUM(H18:H22) -> -5050.141 | I23: =SUM(I18:I22) -> -5769.8417 | J23: =SUM(J18:J22) -> -6435.9589 | ... Q23: =SUM(Q18:Q22) -> -8634.4254
B25: EBIT | C25: =SUM(C23,C14) -> 819.986 | D25: =SUM(D23,D14) -> 1333.355 | E25: =SUM(E23,E14) -> 1328.408 | F25: =SUM(F23,F14) -> 2132.676 | G25: =SUM(G23,G14) -> 2505.697 | H25: =SUM(H23,H14) -> 2026.2487 | I25: =SUM(I23,I14) -> 2283.0781 | J25: =SUM(J23,J14) -> 2523.5006 | ... Q25: =SUM(Q23,Q14) -> 3340.4024
B27: Other income (expense), net | C27: -0.636 | D27: 0.514 | E27: 4.163 | F27: 43.059 | G27: 70.38 | H27: =G27*(1+H11) -> 79.454811 | I27: =H27*(1+I11) -> 89.512224 | J27: =I27*(1+J11) -> 98.927146 | K27: =J27*(1+K11) -> 107.39336 | L27: =K27*(1+L11) -> 114.67251 | M27: =L27*(1+M11) -> 120.61029 | N27: =M27*(1+N11) -> 125.14286 | O27: =N27*(1+O11) -> 128.29399 | ... Q27: =P27*(1+Q11) -> 130.91694
B29: EBT | C29: =SUM(C25,C27) -> 819.35 | D29: =SUM(D25,D27) -> 1333.869 | E29: =SUM(E25,E27) -> 1332.571 | F29: =SUM(F25,F27) -> 2175.735 | G29: =SUM(G25,G27) -> 2576.077 | H29: =SUM(H25,H27) -> 2105.7035 | I29: =SUM(I25,I27) -> 2372.5903 | J29: =SUM(J25,J27) -> 2622.4277 | ... Q29: =SUM(Q25,Q27) -> 3471.3193
B31: Income Tax Expense | C31: -230.437 | D31: -358.547 | E31: -477.771 | F31: -625.545 | G31: -761.461 | H31: ='Supporting Schedules'!I26 -> -638.02817 | I31: ='Supporting Schedules'!J26 -> -718.89486 | J31: ='Supporting Schedules'!K26 -> -794.5956 | K31: ='Supporting Schedules'!L26 -> -862.66824 | L31: ='Supporting Schedules'!M26 -> -921.19631 | M31: ='Supporting Schedules'!N26 -> -968.93903 | N31: ='Supporting Schedules'!O26 -> -1005.3832 | O31: ='Supporting Schedules'!P26 -> -1030.7199 | ... Q31: ='Supporting Schedules'!R26 -> -1051.8098
B32: % of Revenue | C32: =-C31/C10 -> 0.05234969 | D32: =-D31/D10 -> 0.057306848 | E32: =-E31/E10 -> 0.058907581 | F32: =-F31/F10 -> 0.065030348 | G32: =-G31/G10 -> 0.071916503 | H32: =-H31/H10 -> 0.053376466 | I32: =-I31/I10 -> 0.053384256 | J32: =-J31/J10 -> 0.053390112 | ... Q32: =-Q31/Q10 -> 0.053403718
B33: Effective Tax Rate | C33: =-C31/C29 -> 0.28124367 | D33: =-D31/D29 -> 0.26880226 | E33: =-E31/E29 -> 0.35853324 | F33: =-F31/F29 -> 0.28750974 | G33: =-G31/G29 -> 0.29558938 | H33: =-H31/H29 -> 0.303 | I33: =-I31/I29 -> 0.303 | J33: =-J31/J29 -> 0.303 | ... Q33: =-Q31/Q29 -> 0.303
B35: Net Income (Loss) | C35: =SUM(C29,C31) -> 588.913 | D35: =SUM(D29,D31) -> 975.322 | E35: =SUM(E29,E31) -> 854.8 | F35: =SUM(F29,F31) -> 1550.19 | G35: =SUM(G29,G31) -> 1814.616 | H35: =SUM(H29,H31) -> 1467.6754 | I35: =SUM(I29,I31) -> 1653.6954 | J35: =SUM(J29,J31) -> 1827.8321 | ... Q35: =SUM(Q29,Q31) -> 2419.5096
B36: Net Income % | C36: =IFERROR(C35/C10," ") -> 0.13378673 | D36: =IFERROR(D35/D10," ") -> 0.15588648 | E36: =IFERROR(E35/E10," ") -> 0.10539401 | F36: =IFERROR(F35/F10," ") -> 0.16115451 | G36: =IFERROR(G35/G10," ") -> 0.17138217 | H36: =IFERROR(H35/H10," ") -> 0.12278349 | I36: =IFERROR(I35/I10," ") -> 0.12280141 | J36: =IFERROR(J35/J10," ") -> 0.12281488 | ... Q36: =IFERROR(Q35/Q10," ") -> 0.12284618
B38: Depreciation & Amortization | C38: 185.478 | D38: 224.206 | E38: 291.791 | F38: 379.384 | G38: 446.524 | H38: =-'Supporting Schedules'!I77 -> 523.5014 | I38: =-'Supporting Schedules'!J77 -> 601.53501 | J38: =-'Supporting Schedules'!K77 -> 685.98615 | K38: =-'Supporting Schedules'!L77 -> 773.09252 | L38: =-'Supporting Schedules'!M77 -> 859.30403 | M38: =-'Supporting Schedules'!N77 -> 941.41853 | N38: =-'Supporting Schedules'!O77 -> 1016.7248 | O38: =-'Supporting Schedules'!P77 -> 1083.1224 | ... Q38: =-'Supporting Schedules'!R77 -> 1184.2477
B39: EBITDA | C39: =C35+C38 -> 774.391 | D39: =D35+D38 -> 1199.528 | E39: =E35+E38 -> 1146.591 | F39: =F35+F38 -> 1929.574 | G39: =G35+G38 -> 2261.14 | H39: =H35+H38 -> 1991.1768 | I39: =I35+I38 -> 2255.2304 | J39: =J35+J38 -> 2513.8183 | ... Q39: =Q35+Q38 -> 3603.7572
B41: Balance Sheet
B43: Assets
B45: Current Assets
B46: Cash And Cash Equivalents | C46: 1150.517 | D46: 1259.871 | E46: 1154.867 | F46: 2243.971 | G46: 1984.336 | H46: =H154 -> 2488.378 | I46: =I154 -> 2620.006 | J46: =J154 -> 2800.54 | K46: =K154 -> 3034.9753 | L46: =L154 -> 3337.4444 | M46: =M154 -> 3709.5865 | N46: =N154 -> 4137.0183 | O46: =O154 -> 4627.7717 | ... Q46: =Q154 -> 5654.9595
B47: Accounts & Other Recievables | C47: 62.399 | D47: 77.001 | E47: 132.906 | F47: 124.769 | G47: 120.173 | H47: ='Supporting Schedules'!I34 -> 145.7727 | I47: ='Supporting Schedules'!J34 -> 164.22465 | J47: ='Supporting Schedules'!K34 -> 181.49784 | K47: ='Supporting Schedules'!L34 -> 197.03048 | L47: ='Supporting Schedules'!M34 -> 210.38526 | M47: ='Supporting Schedules'!N34 -> 221.27907 | N47: ='Supporting Schedules'!O34 -> 229.5948 | O47: ='Supporting Schedules'!P34 -> 235.37607 | ... Q47: ='Supporting Schedules'!R34 -> 240.1883
B48: Inventory | C48: 647.23 | D48: 966.481 | E48: 1447.367 | F48: 1323.602 | G48: 1442.081 | H48: ='Supporting Schedules'!I50 -> 1561.1454 | I48: ='Supporting Schedules'!J50 -> 1758.7556 | J48: ='Supporting Schedules'!K50 -> 1943.742 | K48: ='Supporting Schedules'!L50 -> 2110.088 | L48: ='Supporting Schedules'!M50 -> 2253.1104 | M48: ='Supporting Schedules'!N50 -> 2369.7771 | N48: ='Supporting Schedules'!O50 -> 2458.834 | O48: ='Supporting Schedules'!P50 -> 2520.7482 | ... Q48: ='Supporting Schedules'!R50 -> 2572.2845
B49: Prepaid and receivable income taxes | C49: 139.126 | D49: 118.928 | E49: 185.641 | F49: 183.733 | G49: 182.253 | H49: =H$10*H94 -> 215.1605 | I49: =I10*I94 -> 242.39558 | J49: =J10*J94 -> 267.89081 | K49: =K10*K94 -> 290.81699 | L49: =L10*L94 -> 310.52865 | M49: =M10*M94 -> 326.60791 | N49: =N10*N94 -> 338.88193 | O49: =O10*O94 -> 347.41508 | P49: =P10*P94 -> 352.48049 | Q49: =Q10*Q94 -> 354.51793
B50: Prepaid Expenses and other current assets | C50: 125.107 | D50: 192.572 | E50: 238.672 | F50: 184.502 | G50: 251.459 | H50: =H$10*H95 -> 262.97394 | I50: =I$10*I95 -> 296.26126 | J50: =J$10*J95 -> 327.42211 | K50: =K$10*K95 -> 355.44299 | L50: =L$10*L95 -> 379.53501 | M50: =M$10*M95 -> 399.18745 | N50: =N$10*N95 -> 414.18903 | O50: =O$10*O95 -> 424.61843 | ... Q50: =Q$10*Q95 -> 551.47233
B51: Total Current Assets | C51: =SUM(C46:C50) -> 2124.379 | D51: =SUM(D46:D50) -> 2614.853 | E51: =SUM(E46:E50) -> 3159.453 | F51: =SUM(F46:F50) -> 4060.577 | G51: =SUM(G46:G50) -> 3980.302 | H51: =SUM(H46:H50) -> 4673.4306 | I51: =SUM(I46:I50) -> 5081.6431 | J51: =SUM(J46:J50) -> 5521.0928 | ... Q51: =SUM(Q46:Q50) -> 9373.4225
B53: Non-Current Assets
...

Sheet Supporting Schedules
B1: Sauder Capital Markets Challenge
B2: =company -> lululemon athletica inc.
B3: Financial Model
B4: Supporting Schedules
B6: Years | D6: 2020 | E6: =D6+1 -> 2021 | F6: =E6+1 -> 2022 | G6: =F6+1 -> 2023 | H6: =G6+1 -> 2024 | I6: =H6+1 -> 2025 | J6: =I6+1 -> 2026 | K6: =J6+1 -> 2027 | L6: =K6+1 -> 2028 | ... R6: =Q6+1 -> 2034
B8: Cost of Goods Sold Schedule
B10: Beginning: Revenue | D10: ='Financial Statements'!C10 -> 4401.879 | E10: ='Financial Statements'!D10 -> 6256.617 | F10: ='Financial Statements'!E10 -> 8110.518 | G10: ='Financial Statements'!F10 -> 9619.278 | H10: ='Financial Statements'!G10 -> 10588.126 | I10: ='Financial Statements'!H10 -> 11953.361 | J10: ='Financial Statements'!I10 -> 13466.421 | K10: ='Financial Statements'!J10 -> 14882.823 | ... R10: ='Financial Statements'!Q10 -> 19695.44
B11: Less: COGS | D11: ='Financial Statements'!C12 -> -1937.888 | E11: ='Financial Statements'!D12 -> -2648.052 | F11: ='Financial Statements'!E12 -> -3618.178 | G11: ='Financial Statements'!F12 -> -4009.873 | H11: ='Financial Statements'!G12 -> -4317.315 | I11: =-(I10-I12) -> -4876.9713 | J11: =-(J10-J12) -> -5413.5012 | K11: =-(K10-K12) -> -5923.3636 | L11: =-(L10-L12) -> -6397.9737 | M11: =-(M10-M12) -> -6797.1271 | N11: =-(N10-N12) -> -7112.7945 | O11: =-(O10-O12) -> -7380.0954 | P11: =-(P10-P12) -> -7565.9283 | ... R11: =-(R10-R12) -> -7720.6126
B12: Equals: Gross Profit | D12: =D10+D11 -> 2463.991 | E12: =E10+E11 -> 3608.565 | F12: =F10+F11 -> 4492.34 | G12: =G10+G11 -> 5609.405 | H12: =H10+H11 -> 6270.811 | I12: =I10*I13 -> 7076.3898 | J12: =J10*J13 -> 8052.9198 | K12: =K10*K13 -> 8959.4595 | L12: =L10*L13 -> 9758.5256 | M12: =M10*M13 -> 10454.464 | N12: =N10*N13 -> 11032.089 | O12: =O10*O13 -> 11446.679 | P12: =P10*P13 -> 11734.909 | ... R12: =R10*R13 -> 11974.828
B13: Gross Margin | D13: =D12/D10 -> 0.55975891 | E13: =E12/E10 -> 0.57675977 | F13: =F12/F10 -> 0.55389064 | G13: =G12/G10 -> 0.583142 | H13: =H12/H10 -> 0.59224937 | I13: 0.592 | J13: 0.598 | K13: 0.602 | L13: 0.604 | M13: 0.606 | N13: 0.608 | O13: =N13 -> 0.608 | P13: =O13 -> 0.608 | Q13: =P13 -> 0.608 | R13: =Q13 -> 0.608
B15: Selling, General & Administrative Schedule
B17: Beginning: Gross Profit | D17: =D12 -> 2463.991 | E17: =E12 -> 3608.565 | F17: =F12 -> 4492.34 | G17: =G12 -> 5609.405 | H17: =H12 -> 6270.811 | I17: =I12 -> 7076.3898 | J17: =J12 -> 8052.9198 | K17: =K12 -> 8959.4595 | ... R17: =R12 -> 11974.828
B18: Less: SG&A | D18: ='Financial Statements'!C18 -> -1609.003 | E18: ='Financial Statements'!D18 -> -2225.034 | F18: ='Financial Statements'!E18 -> -2757.447 | G18: ='Financial Statements'!F18 -> -3397.218 | H18: ='Financial Statements'!G18 -> -3762.379 | I18: =-(I17-I20-I19) -> -5047.0534 | J18: =-(J17-J20-J19) -> -5766.3632 | K18: =-(K17-K20-K19) -> -6432.1146 | L18: =-(L17-L20-L19) -> -7014.6557 | M18: =-(M17-M20-M19) -> -7524.4289 | N18: =-(N17-N20-N19) -> -7950.1942 | O18: =-(O17-O20-O19) -> -8248.862 | P18: =-(P17-P20-P19) -> -8456.5018 | ... R18: =-(R17-R20-R19) -> -8629.3379
B19: Less: Other Operating Expenses | D19: =SUM('Financial Statements'!C19:C22) -> -35.002 | E19: =SUM('Financial Statements'!D19:D22) -> -50.176 | F19: =SUM('Financial Statements'!E19:E22) -> -406.485 | G19: =SUM('Financial Statements'!F19:F22) -> -79.511 | H19: =SUM('Financial Statements'!G19:G22) -> -2.735 | I19: =H19 -> -2.735 | J19: =I19 -> -2.735 | K19: =J19 -> -2.735 | L19: =K19 -> -2.735 | M19: =L19 -> -2.735 | N19: =M19 -> -2.735 | O19: =N19 -> -2.735 | P19: =O19 -> -2.735 | ... R19: =Q19 -> -2.735
B20: Equals: Operating Income | D20: =SUM(D17:D19) -> 819.986 | E20: =SUM(E17:E19) -> 1333.355 | F20: =SUM(F17:F19) -> 1328.408 | G20: =SUM(G17:G19) -> 2132.676 | H20: =SUM(H17:H19) -> 2505.697 | I20: =I10*I21 -> 2032.0714 | J20: =J10*J21 -> 2289.2916 | K20: =K10*K21 -> 2530.0799 | L20: =L10*L21 -> 2746.6049 | M20: =M10*M21 -> 2932.7706 | N20: =N10*N21 -> 3084.6303 | O20: =O10*O21 -> 3200.5516 | P20: =P10*P21 -> 3281.1424 | ... R20: =R10*R21 -> 3348.2249
B21: % Margin | D21: =D20/D10 -> 0.1862809 | E21: =E20/E10 -> 0.21311117 | F21: =F20/F10 -> 0.16378831 | G21: =G20/G10 -> 0.22170853 | H21: =H20/H10 -> 0.2366516 | I21: 0.17 | J21: =I21 -> 0.17 | K21: =J21 -> 0.17 | L21: =K21 -> 0.17 | M21: =L21 -> 0.17 | N21: =M21 -> 0.17 | O21: =N21 -> 0.17 | P21: =O21 -> 0.17 | Q21: =P21 -> 0.17 | R21: =Q21 -> 0.17
B23: Tax Rate Schedule
B25: Earnings Before Tax (EBT) | D25: ='Financial Statements'!C29 -> 819.35 | E25: ='Financial Statements'!D29 -> 1333.869 | F25: ='Financial Statements'!E29 -> 1332.571 | G25: ='Financial Statements'!F29 -> 2175.735 | H25: ='Financial Statements'!G29 -> 2576.077 | I25: ='Financial Statements'!H29 -> 2105.7035 | J25: ='Financial Statements'!I29 -> 2372.5903 | K25: ='Financial Statements'!J29 -> 2622.4277 | ... R25: ='Financial Statements'!Q29 -> 3471.3193
B26: Less: Tax Expense | D26: ='Financial Statements'!C31 -> -230.437 | E26: ='Financial Statements'!D31 -> -358.547 | F26: ='Financial Statements'!E31 -> -477.771 | G26: ='Financial Statements'!F31 -> -625.545 | H26: ='Financial Statements'!G31 -> -761.461 | I26: =-I25*I27 -> -638.02817 | J26: =-J25*J27 -> -718.89486 | K26: =-K25*K27 -> -794.5956 | L26: =-L25*L27 -> -862.66824 | M26: =-M25*M27 -> -921.19631 | N26: =-N25*N27 -> -968.93903 | O26: =-O25*O27 -> -1005.3832 | P26: =-P25*P27 -> -1030.7199 | ... R26: =-R25*R27 -> -1051.8098
B27: Effective Tax Rate | D27: =-D26/D25 -> 0.28124367 | E27: =-E26/E25 -> 0.26880226 | F27: =-F26/F25 -> 0.35853324 | G27: =-G26/G25 -> 0.28750974 | H27: =-H26/H25 -> 0.29558938 | I27: 0.303 | J27: =I27 -> 0.303 | K27: =J27 -> 0.303 | L27: =K27 -> 0.303 | M27: =L27 -> 0.303 | N27: =M27 -> 0.303 | O27: =N27 -> 0.303 | P27: =O27 -> 0.303 | Q27: =P27 -> 0.303 | R27: =Q27 -> 0.303
B29: Working Capital - FILL OUT IF NEEDED
B31: Accounts Receivable
B32: Beginning A/R Balance | E32: =D34 -> 62.399 | F32: =E34 -> 77.001 | G32: =F34 -> 132.906 | H32: =G34 -> 124.769 | I32: =H34 -> 120.173 | J32: =I34 -> 145.7727 | K32: =J34 -> 164.22465 | L32: =K34 -> 181.49784 | ... R32: =Q34 -> 238.80792
B33: Increase / (Decrease) | E33: =E34-E32 -> 14.602 | F33: =F34-F32 -> 55.905 | G33: =G34-G32 -> -8.137 | H33: =H34-H32 -> -4.596 | I33: =I34-I32 -> 25.599696 | J33: =J34-J32 -> 18.45195 | K33: =K34-K32 -> 17.273196 | L33: =L34-L32 -> 15.532638 | ... R33: =R34-R32 -> 1.3803787
B34: Ending A/R Balance | D34: ='Financial Statements'!C47 -> 62.399 | E34: ='Financial Statements'!D47 -> 77.001 | F34: ='Financial Statements'!E47 -> 132.906 | G34: ='Financial Statements'!F47 -> 124.769 | H34: ='Financial Statements'!G47 -> 120.173 | I34: =I10/I36 -> 145.7727 | J34: =J10/J36 -> 164.22465 | K34: =K10/K36 -> 181.49784 | L34: =L10/L36 -> 197.03048 | M34: =M10/M36 -> 210.38526 | N34: =N10/N36 -> 221.27907 | O34: =O10/O36 -> 229.5948 | P34: =P10/P36 -> 235.37607 | ... R34: =R10/R36 -> 240.1883
B36: A/R Turnover | D36: =D$10/AVERAGE(D32,D34) -> 70.544063 | E36: =E$10/AVERAGE(E32,E34) -> 89.76495 | F36: =F$10/AVERAGE(F32,F34) -> 77.277251 | G36: =G$10/AVERAGE(G32,G34) -> 74.662098 | H36: =H$10/AVERAGE(H32,H34) -> 86.454148 | I36: 82 | J36: =I36 -> 82 | K36: =J36 -> 82 | L36: =K36 -> 82 | M36: =L36 -> 82 | N36: =M36 -> 82 | O36: =N36 -> 82 | P36: =O36 -> 82 | Q36: =P36 -> 82 | R36: =Q36 -> 82
B37: Days Sales Outstanding | D37: =365/D36 -> 5.1740711 | E37: =365/E36 -> 4.0661751 | F37: =365/F36 -> 4.7232529 | G37: =365/G36 -> 4.888692 | H37: =365/H36 -> 4.2218911 | I37: =365/I36 -> 4.4512195 | J37: =365/J36 -> 4.4512195 | K37: =365/K36 -> 4.4512195 | ... R37: =365/R36 -> 4.4512195
B39: Accounts Payable
B40: Beginning A/P Balance | E40: =D42 -> 172.246 | F40: =E42 -> 289.728 | G40: =F42 -> 172.732 | H40: =G42 -> 348.441 | I40: =H42 -> 271.406 | J40: =I42 -> 332.03781 | K40: =J42 -> 374.06725 | L40: =K42 -> 413.41175 | ... R40: =Q42 -> 543.95137
B41: Increase / (Decrease) | E41: =E42-E40 -> 117.482 | F41: =F42-F40 -> -116.996 | G41: =G42-G40 -> 175.709 | H41: =H42-H40 -> -77.035 | I41: =I42-I40 -> 60.631808 | J41: =J42-J40 -> 42.029442 | K41: =K42-K40 -> 39.344501 | L41: =L42-L40 -> 35.379897 | ... R41: =R42-R40 -> 3.144196
B42: Ending A/P Balance | D42: ='Financial Statements'!C65 -> 172.246 | E42: ='Financial Statements'!D65 -> 289.728 | F42: ='Financial Statements'!E65 -> 172.732 | G42: ='Financial Statements'!F65 -> 348.441 | H42: ='Financial Statements'!G65 -> 271.406 | I42: =I$10/I44 -> 332.03781 | J42: =J$10/J44 -> 374.06725 | K42: =K$10/K44 -> 413.41175 | L42: =L$10/L44 -> 448.79165 | M42: =M$10/M44 -> 479.21088 | N42: =N$10/N44 -> 504.02455 | O42: =O$10/O44 -> 522.96594 | P42: =P$10/P44 -> 536.13438 | ... R42: =R$10/R44 -> 547.09557
B44: A/P Turnover | D44: =D$10/AVERAGE(D40,D42) -> 25.555769 | E44: =E$10/AVERAGE(E40,E42) -> 27.086446 | F44: =F$10/AVERAGE(F40,F42) -> 35.075544 | G44: =G$10/AVERAGE(G40,G42) -> 36.913954 | H44: =H$10/AVERAGE(H40,H42) -> 34.163676 | I44: 36 | J44: =I44 -> 36 | K44: =J44 -> 36 | L44: =K44 -> 36 | M44: =L44 -> 36 | N44: =M44 -> 36 | O44: =N44 -> 36 | P44: =O44 -> 36 | Q44: =P44 -> 36 | R44: =Q44 -> 36
B45: Days Payables Outstanding | D45: =365/D44 -> 14.282489 | E45: =365/E44 -> 13.475374 | F45: =365/F44 -> 10.406111 | G45: =365/G44 -> 9.8878598 | H45: =365/H44 -> 10.683862 | I45: =365/I44 -> 10.138889 | J45: =365/J44 -> 10.138889 | K45: =365/K44 -> 10.138889 | ... R45: =365/R44 -> 10.138889
B47: Inventory
B48: Beginning Inventory Balance | E48: =D50 -> 647.23 | F48: =E50 -> 966.481 | G48: =F50 -> 1447.367 | H48: =G50 -> 1323.602 | I48: =H50 -> 1442.081 | J48: =I50 -> 1561.1454 | K48: =J50 -> 1758.7556 | L48: =K50 -> 1943.742 | ... R48: =Q50 -> 2557.5014
B49: Increase / (Decrease) | E49: =E50-E48 -> 319.251 | F49: =F50-F48 -> 480.886 | G49: =G50-G48 -> -123.765 | H49: =H50-H48 -> 118.479 | I49: =I50-I48 -> 119.06436 | J49: =J50-J48 -> 197.61023 | K49: =K50-K48 -> 184.98642 | L49: =L50-L48 -> 166.346 | ... R49: =R50-R48 -> 14.783097
B50: Ending Inventory Balance | D50: ='Financial Statements'!C48 -> 647.23 | E50: ='Financial Statements'!D48 -> 966.481 | F50: ='Financial Statements'!E48 -> 1447.367 | G50: ='Financial Statements'!F48 -> 1323.602 | H50: ='Financial Statements'!G48 -> 1442.081 | I50: =I$10/I52 -> 1561.1454 | J50: =J$10/J52 -> 1758.7556 | K50: =K$10/K52 -> 1943.742 | L50: =L$10/L52 -> 2110.088 | M50: =M$10/M52 -> 2253.1104 | N50: =N$10/N52 -> 2369.7771 | O50: =O$10/O52 -> 2458.834 | P50: =P$10/P52 -> 2520.7482 | ... R50: =R$10/R52 -> 2572.2845
B52: Inventory Turnover | D52: =D$10/AVERAGE(D48,D50) -> 6.8011047 | E52: =E$10/AVERAGE(E48,E50) -> 7.7543216 | F52: =F$10/AVERAGE(F48,F50) -> 6.7199907 | G52: =G$10/AVERAGE(G48,G50) -> 6.9428983 | H52: =H$10/AVERAGE(H48,H50) -> 7.6567893 | I52: =H52 -> 7.6567893 | J52: =I52 -> 7.6567893 | K52: =J52 -> 7.6567893 | L52: =K52 -> 7.6567893 | M52: =L52 -> 7.6567893 | N52: =M52 -> 7.6567893 | O52: =N52 -> 7.6567893 | P52: =O52 -> 7.6567893 | ... R52: =Q52 -> 7.6567893
B53: Days Inventory Outstanding | D53: =365/D52 -> 53.667752 | E53: =365/E52 -> 47.070527 | F53: =365/F52 -> 54.315552 | G53: =365/G52 -> 52.571705 | H53: =365/H52 -> 47.670112 | I53: =365/I52 -> 47.670112 | J53: =365/J52 -> 47.670112 | K53: =365/K52 -> 47.670112 | ... R53: =365/R52 -> 47.670112
B55: Increase (Decrease) in A/R | E55: ='Financial Statements'!C47-'Financial Statements'!D47 -> -14.602 | F55: ='Financial Statements'!D47-'Financial Statements'!E47 -> -55.905 | G55: ='Financial Statements'!E47-'Financial Statements'!F47 -> 8.137 | H55: ='Financial Statements'!F47-'Financial Statements'!G47 -> 4.596 | I55: ='Financial Statements'!G47-'Financial Statements'!H47 -> -25.599696 | J55: ='Financial Statements'!H47-'Financial Statements'!I47 -> -18.45195 | K55: ='Financial Statements'!I47-'Financial Statements'!J47 -> -17.273196 | L55: ='Financial Statements'!J47-'Financial Statements'!K47 -> -15.532638 | ... R55: ='Financial Statements'!P47-'Financial Statements'!Q47 -> -1.3803787
...

Sheet Revenue Build Schedule
A1: Sauder Capital Markets Challenge
A2: =company -> lululemon athletica inc.
A3: Financial Model
A4: DCF Valuation
A5: Years | B5: 2020 | C5: =B5+1 -> 2021 | D5: =C5+1 -> 2022 | E5: =D5+1 -> 2023 | F5: =E5+1 -> 2024 | G5: =F5+1 -> 2025 | H5: =G5+1 -> 2026 | I5: =H5+1 -> 2027 | J5: =I5+1 -> 2028 | ... P5: =O5+1 -> 2034
A6: For the year ended | B6: =EOMONTH(C6,-12) -> 44227 | C6: 44591 | D6: 44955 | E6: 45319 | F6: 45690 | G6: =EOMONTH(F6,11) -> 46053 | H6: =EOMONTH(G6,12) -> 46418 | I6: =EOMONTH(H6,12) -> 46783 | J6: =EOMONTH(I6,12) -> 47149 | K6: =EOMONTH(J6,12) -> 47514 | L6: =EOMONTH(K6,12) -> 47879 | M6: =EOMONTH(L6,12) -> 48244 | N6: =EOMONTH(M6,12) -> 48610 | O6: =EOMONTH(N6,12) -> 48975 | P6: =EOMONTH(O6,12) -> 49340
A7: Revenue Build - Base Case
A8: Revenue by geographies and gender
A9: Americas | B9: =SUM(B10:B11) -> 3777.74 | C9: =SUM(C10:C11) -> 5299.906 | D9: =SUM(D10:D11) -> 6817.454 | E9: 7631.647 | F9: 7928.156 | G9: =G24*G44 -> 8501.5235 | H9: =H24*H44 -> 9072.645 | I9: =I24*I44 -> 9635.5801 | J9: =J24*J44 -> 10184.103 | K9: =K24*K44 -> 10711.809 | L9: =L24*L44 -> 11212.232 | M9: =M24*M44 -> 11678.972 | N9: =N24*N44 -> 12105.828 | ... P9: =P24*P44 -> 12816.875
A10: United States | B10: 3105.133 | C10: 4345.687 | D10: 5654.343
A11: Canada | B11: 672.607 | C11: 954.219 | D11: 1163.111
A12: % Revenue Growth | C12: =C9/B9-1 -> 0.40293032 | D12: =D9/C9-1 -> 0.28633489 | E12: =E9/D9-1 -> 0.11942772 | F12: =F9/E9-1 -> 0.038852557 | G12: =G9/F9-1 -> 0.072320411 | H12: =H9/G9-1 -> 0.067178719 | I12: =I9/H9-1 -> 0.062047527 | J12: =J9/I9-1 -> 0.056926836 | ... P12: =P9/O9-1 -> 0.026423185
A13: % of Total Revenue | B13: =B9/B20 -> 0.85821078 | C13: =C9/C20 -> 0.84708813 | D13: =D9/D20 -> 0.84056949 | E13: =E9/E20 -> 0.79337004 | F13: =F9/F20 -> 0.74877802 | G13: =G9/G$20 -> 0.71122452 | H13: =H9/H$20 -> 0.67372355 | I13: =I9/I$20 -> 0.6474296 | J13: =J9/J$20 -> 0.63034096 | K13: =K9/K$20 -> 0.62091716 | L13: =L9/L$20 -> 0.61792803 | M13: =M9/M$20 -> 0.62033849 | N13: =N9/N$20 -> 0.62721776 | ... P13: =P9/P$20 -> 0.65075339
A14: China Mainland | B14: 297.69 | C14: 520.372 | D14: 681.633 | E14: 963.76 | F14: 1361.337 | G14: =G29*G47 -> 1865.1206 | H14: =H29*H47 -> 2477.3484 | I14: =I29*I47 -> 3188.5565 | J14: =J29*J47 -> 3974.7435 | K14: =K29*K47 -> 4796.2972 | L14: =L29*L47 -> 5599.5298 | M14: =M29*M47 -> 6321.2678 | N14: =N29*N47 -> 6896.2719 | ... P14: =P29*P47 -> 7390.3511
A15: % Revenue Growth | C15: =C14/B14-1 -> 0.74803319 | D15: =D14/C14-1 -> 0.30989561 | E15: =E14/D14-1 -> 0.41389868 | F15: =F14/E14-1 -> 0.41252698 | G15: =G14/F14-1 -> 0.37006528 | H15: =H14/G14-1 -> 0.32825109 | I15: =I14/H14-1 -> 0.28708439 | J15: =J14/I14-1 -> 0.2465652 | ... P15: =P14/O14-1 -> 0.017047526
A16: % of Total Revenue | B16: =B14/B20 -> 0.067627938 | C16: =C14/C20 -> 0.083171465 | D16: =D14/D20 -> 0.084043091 | E16: =E14/E20 -> 0.10019047 | F16: =F14/F20 -> 0.12857204 | G16: =G14/G$20 -> 0.15603315 | H16: =H14/H$20 -> 0.18396487 | I16: =I14/I$20 -> 0.21424406 | J16: =J14/J$20 -> 0.24601515 | K16: =K14/K$20 -> 0.27802056 | L16: =L14/L$20 -> 0.30860102 | M16: =M14/M$20 -> 0.33575948 | N16: =N14/N$20 -> 0.35730428 | ... P16: =P14/P$20 -> 0.37523157
A17: Rest of World | B17: 326.449 | C17: 436.339 | D17: 611.431 | E17: 1023.871 | F17: 1298.633 | G17: =G34*(G61+G74) -> 1586.717 | H17: =H34*(H61+H74) -> 1916.4276 | I17: =I34*(I61+I74) -> 2272.7906 | J17: =J34*(J61+J74) -> 2646.1535 | K17: =K34*(K61+K74) -> 3023.8848 | L17: =L34*(L61+L74) -> 3390.8441 | M17: =M34*(M61+M74) -> 3730.2035 | N17: =N34*(N61+N74) -> 4024.5858 | ... P17: =P34*(P61+P74) -> 4414.4661
A18: % Revenue Growth | C18: 0.53 | D18: =D17/C17-1 -> 0.40127516 | E18: =E17/D17-1 -> 0.67454872 | F18: =F17/E17-1 -> 0.26835607 | G18: =G17/F17-1 -> 0.22183638 | H18: =H17/G17-1 -> 0.20779419 | I18: =I17/H17-1 -> 0.18595172 | J18: =J17/I17-1 -> 0.16427509 | K18: =K17/J17-1 -> 0.14274731 | ... P18: =P17/O17-1 -> 0.036884679
A19: % of Total Revenue | B19: =B17/B20 -> 0.074161284 | C19: =C17/C20 -> 0.069740404 | D19: =D17/D20 -> 0.075387417 | E19: =E17/E20 -> 0.10643949 | F19: =F17/F20 -> 0.12264994 | G19: =G17/G$20 -> 0.13274233 | H19: =H17/H$20 -> 0.14231158 | I19: =I17/I$20 -> 0.15271233 | J19: =J17/J$20 -> 0.1637826 | K19: =K17/K$20 -> 0.1752815 | L19: =L17/L$20 -> 0.18687604 | M19: =M17/M$20 -> 0.19813291 | N19: =N17/N$20 -> 0.20851871 | ... P19: =P17/P$20 -> 0.22413645
A20: Net Revenue | B20: ='Financial Statements'!C10 -> 4401.879 | C20: ='Financial Statements'!D10 -> 6256.617 | D20: ='Financial Statements'!E10 -> 8110.518 | E20: ='Financial Statements'!F10 -> 9619.278 | F20: ='Financial Statements'!G10 -> 10588.126 | G20: =SUM(G17+G14+G9) -> 11953.361 | H20: =SUM(H17+H14+H9) -> 13466.421 | I20: =H20*(1+I21) -> 14882.823 | J20: =I20*(1+J21) -> 16156.499 | K20: =J20*(1+K21) -> 17251.592 | L20: =K20*(1+L21) -> 18144.884 | M20: =L20*(1+M21) -> 18826.774 | N20: =M20*(1+N21) -> 19300.838 | O20: =N20*(1+O21) -> 19582.249 | P20: =O20*(1+P21) -> 19695.44
A21: Growth % | C21: 0.53 | D21: =D20/C20-1 -> 0.29631045 | E21: =E20/D20-1 -> 0.18602511 | F21: =F20/E20-1 -> 0.10071941 | G21: =G20/F20-1 -> 0.1289402 | H21: =H20/G20-1 -> 0.12658029 | I21: =H21+$S$21-($S$22*I22) -> 0.10518029 | J21: =I21+$S$21-($S$22*J22) -> 0.085580289 | K21: =J21+$S$21-($S$22*K22) -> 0.067780289 | L21: =K21+$S$21-($S$22*L22) -> 0.051780289 | M21: =L21+$S$21-($S$22*M22) -> 0.037580289 | N21: =M21+$S$21-($S$22*N22) -> 0.025180289 | O21: =N21+$S$21-($S$22*O22) -> 0.014580289 | P21: =O21+$S$21-($S$22*P22) -> 0.0057802888 | R21: Step: | S21: -0.025 | AE21: Assumption - Lululemon will enjoy increased growth around FY25E - FY26E, but will see a decline in growth as they maximize their market share
H22: 1 | I22: 2 | J22: 3 | K22: 4 | L22: 5 | M22: 6 | N22: 7 | O22: 8 | P22: 9 | R22: Step Accel: | S22: -0.0018 | AE22: Assumption - Lululemon will enjoy increased growth around FY25E - FY26E, but will see a decline in growth as they maximize their market share
A23: Annual sales per store (millions)
A24: Americas | B24: =B9/B44 -> 10.020531 | C24: =C9/C44 -> 13.694848 | D24: =D9/D44 -> 16.270773 | E24: =E9/E44 -> 17.423852 | F24: =F9/F44 -> 17.160511 | G24: =F24*(1+G28) -> 17.503721 | H24: =G24*(1+H28) -> 17.82754 | I24: =H24*(1+I28) -> 18.130608 | J24: =I24*(1+J28) -> 18.411632 | K24: =J24*(1+K28) -> 18.669395 | L24: =K24*(1+L28) -> 18.902763 | M24: =L24*(1+M28) -> 19.110693 | N24: =M24*(1+N28) -> 19.292245 | ... P24: =O24*(1+P28) -> 19.572985
A25: Sales (Male) | B25: =B24*B$86 -> 2.169846 | C25: =C24*C$86 -> 3.3617579 | D25: =D24*D$86 -> 3.9252027 | E25: =E24*E$86 -> 4.0805177 | F25: =F24*F$86 -> 4.1464474 | G25: =G24*G$86 -> 4.6156417 | H25: =H24*H$86 -> 5.0669944 | I25: =I24*I$86 -> 5.4885611 | ... P25: =P24*P$86 -> 6.8010049
A26: Sales (Female) | B26: =B24*B$83 -> 6.9428706 | C26: =C24*C$83 -> 9.1313955 | D26: =D24*D$83 -> 10.551861 | E26: =E24*E$83 -> 11.135025 | F26: =F24*F$83 -> 10.846957 | G26: =G24*G$83 -> 10.730316 | H26: =H24*H$83 -> 10.61416 | I26: =I24*I$83 -> 10.507275 | ... P26: =P24*P$83 -> 10.602883
A27: Sales (Other) | B27: =B24*B$89 -> 0.90781399 | C27: =C24*C$89 -> 1.2016941 | D27: =D24*D$89 -> 1.7034331 | E27: =E24*E$89 -> 2.2083093 | F27: =F24*F$89 -> 2.1671062 | G27: =G24*G$89 -> 2.1577633 | H27: =H24*H$89 -> 2.1463859 | I27: =I24*I$89 -> 2.134772 | ... P27: =P24*P$89 -> 2.1690976
A28: Growth % (Total) | C28: =C24/B24-1 -> 0.36667889 | D28: =D24/C24-1 -> 0.18809452 | E28: =E24/D24-1 -> 0.070868072 | F28: =F24/E24-1 -> -0.01511381 | G28: 0.02 | H28: =G28+$S28 -> 0.0185 | I28: =H28+$S28 -> 0.017 | J28: =I28+$S28 -> 0.0155 | K28: =J28+$S28 -> 0.014 | L28: =K28+$S28 -> 0.0125 | M28: =L28+$S28 -> 0.011 | N28: =M28+$S28 -> 0.0095 | O28: =N28+$S28 -> 0.008 | P28: =O28+$S28 -> 0.0065 | R28: Step: | S28: -0.0015 | AE28: Assumption - Lululemon has high brand exposure in North America, so their rate of expansion will gradually slow down
A29: China Mainland | B29: =B14/B47 -> 6.7656818 | C29: =C14/C47 -> 7.4338857 | D29: =D14/D47 -> 6.8851818 | E29: =E14/E47 -> 7.5886614 | F29: =F14/F47 -> 9.0154768 | G29: =F29*(1+G33) -> 10.55279 | H29: =G29*(1+H33) -> 12.167572 | I29: =H29*(1+I33) -> 13.816514 | J29: =I29*(1+J33) -> 15.44713 | K29: =J29*(1+K33) -> 16.999866 | L29: =K29*(1+L33) -> 18.411184 | M29: =L29*(1+M33) -> 19.617473 | N29: =M29*(1+N33) -> 20.559492 | ... P29: =O29*(1+P33) -> 21.462796
A30: Sales (Male) | B30: =B29*B$86 -> 1.4650409 | C30: =C29*C$86 -> 1.8248413 | D30: =D29*D$86 -> 1.6609988 | E30: =E29*E$86 -> 1.7771999 | F30: =F29*F$86 -> 2.1783851 | G30: =G29*G$86 -> 2.7827168 | H30: =H29*H$86 -> 3.4583021 | I30: =I29*I$86 -> 4.1825833 | ... P30: =P29*P$86 -> 7.4576554
A31: Sales (Female) | B31: =B29*B$83 -> 4.6877012 | C31: =C29*C$83 -> 4.9567365 | D31: =D29*D$83 -> 4.4651525 | E31: =E29*E$83 -> 4.8496701 | F31: =F29*F$83 -> 5.6985769 | G31: =G29*G$83 -> 6.4691831 | H31: =H29*H$83 -> 7.2443281 | I31: =I29*I$83 -> 8.0071174 | ... P31: =P29*P$83 -> 11.626612
A32: Sales (Other) | B32: =B29*B$89 -> 0.61293967 | C32: =C29*C$89 -> 0.65230786 | D32: =D29*D$89 -> 0.7208291 | E32: =E29*E$89 -> 0.96179145 | F32: =F29*F$89 -> 1.1385148 | G32: =G29*G$89 -> 1.3008904 | H32: =H29*H$89 -> 1.4649416 | I32: =I29*I$89 -> 1.6268128 | ... P32: =P29*P$89 -> 2.3785283
A33: Growth % (Total) | C33: =C29/B29-1 -> 0.098763719 | D33: =D29/C29-1 -> -0.073811183 | E33: =E29/D29-1 -> 0.10217299 | F33: =F29/E29-1 -> 0.18801938 | G33: =F33+$S33 -> 0.17051938 | H33: =G33+$S33 -> 0.15301938 | I33: =H33+$S33 -> 0.13551938 | J33: =I33+$S33 -> 0.11801938 | K33: =J33+$S33 -> 0.10051938 | L33: =K33+$S33 -> 0.083019379 | M33: =L33+$S33 -> 0.065519379 | N33: =M33+$S33 -> 0.048019379 | ... P33: =O33+$S33 -> 0.013019379 | R33: Step: | S33: -0.0175 | AE33: Assumption - Lululemon will continue to increase brand awareness in China, which currently sits around 15% (TD Cowen, 2025). Numbers decrease over time due to the mathematical properties of percentages
A34: Rest of World | B34: =B17/(B61+B74) -> 3.26449 | C34: =C17/(C61+C74) -> 3.7293932 | D34: =D17/(D61+D74) -> 4.463 | E34: =E17/(E61+E74) -> 7.0128151 | F34: =F17/(F61+F74) -> 8.4326818 | G34: =F34*(1+G38) -> 9.9755881 | H34: =G34*(1+H38) -> 11.606272 | I34: =H34*(1+I38) -> 13.277197 | J34: =I34*(1+J38) -> 14.929776 | K34: =J34*(1+K38) -> 16.496917 | L34: =K34*(1+L38) -> 17.906866 | M34: =L34*(1+M38) -> 19.088136 | N34: =M34*(1+N38) -> 19.975113 | ... P34: =O34*(1+P38) -> 20.666976
A35: Sales (Male) | B35: =B34*B$86 -> 0.70689275 | C35: =C34*C$86 -> 0.91547692 | D35: =D34*D$86 -> 1.0766655 | E35: =E34*E$86 -> 1.6423416 | F35: =F34*F$86 -> 2.0375659 | G35: =G34*G$86 -> 2.6305115 | H35: =H34*H$86 -> 3.2987679 | I35: =I34*I$86 -> 4.0193196 | ... P35: =P34*P$86 -> 7.1811327
A36: Sales (Female) | B36: =B34*B$83 -> 2.2618495 | C36: =C34*C$83 -> 2.4866698 | D36: =D34*D$83 -> 2.8943282 | E36: =E34*E$83 -> 4.4816652 | F36: =F34*F$83 -> 5.3301991 | G36: =G34*G$83 -> 6.1153405 | H36: =H34*H$83 -> 6.9101415 | I36: =I34*I$83 -> 7.6945661 | ... P36: =P34*P$83 -> 11.195509
A37: Sales (Other) | B37: =B34*B$89 -> 0.29574779 | C37: =C34*C$89 -> 0.32724642 | D37: =D34*D$89 -> 0.46724406 | E37: =E34*E$89 -> 0.88880834 | F37: =F34*F$89 -> 1.0649168 | G37: =G34*G$89 -> 1.2297361 | H37: =H34*H$89 -> 1.3973626 | I37: =I34*I$89 -> 1.5633115 | ... P37: =P34*P$89 -> 2.2903347
A38: Growth % (Total) | C38: =C34/B34-1 -> 0.14241219 | D38: =D34/C34-1 -> 0.19670944 | E38: =E34/D34-1 -> 0.57132312 | F38: =F34/E34-1 -> 0.20246745 | G38: =F38+$S38 -> 0.18296745 | H38: =G38+$S38 -> 0.16346745 | I38: =H38+$S38 -> 0.14396745 | J38: =I38+$S38 -> 0.12446745 | K38: =J38+$S38 -> 0.10496745 | L38: =K38+$S38 -> 0.085467445 | M38: =L38+$S38 -> 0.065967445 | N38: =M38+$S38 -> 0.046467445 | ... P38: =O38+$S38 -> 0.0074674451 | R38: Step: | S38: -0.0195 | AE38: Assumption - Lululemon will expand more rapidly in EMEA/APAC markets, necessitating a more rapid decline in growth to ensure long-term figures don't eclipse projected global economic growth
A40: Company-operated stores
A41: United States | B41: 315 | C41: 324 | D41: 350 | E41: 367 | F41: 374 | G41: =F41*(1+G$45) -> 393.18415 | H41: =G41*(1+H$45) -> 411.9762 | I41: =H41*(1+I$45) -> 430.22449 | J41: =I41*(1+J$45) -> 447.77529 | K41: =J41*(1+K$45) -> 464.47485 | L41: =K41*(1+L$45) -> 480.17156 | M41: =L41*(1+M$45) -> 494.71813 | N41: =M41*(1+N$45) -> 507.97386 | ... P41: =O41*(1+P$45) -> 530.0962
...

Sheet DCF Valuation
B1: Sauder Capital Markets Challenge
B2: =company -> lululemon athletica inc.
B3: Financial Model
B4: DCF Valuation
B6: Input Assumptions
B8: Capital Structure
B9: Equity | C9: 4324
B10: % Equity | C10: =IFERROR(C9/C13,"") -> 0.73288136
B11: Debt | C11: 1576
B12: % Debt | C12: =IFERROR(C11/C13,"") -> 0.26711864
B13: Total Capitalization | C13: =SUM(C9,C11) -> 5900
B16: Weighted Average Cost of Capital (WACC)
B17: Expected Market Return | C17: 0.12
B18: Risk Free Rate | C18: 0.04112
B19: Market Risk Premium | C19: =rm-rf -> 0.07888
B20: Beta | C20: 1.05
B21: Cost of Equity | C21: =rf+beta*mrp -> 0.123944
B22: Pre-Tax Cost of Debt | C22: ='Supporting Schedules'!I71 -> 0.05112
B23: Effective Tax Rate | C23: ='Supporting Schedules'!H27 -> 0.29558938
B24: After Tax Cost Of Debt | C24: =costofdebt*(1-taxrate) -> 0.036009471
B25: WACC | C25: =IFERROR(C10*re+C12*rd,"") -> 0.10045505
B28: Unlevered Free Cash Flow Calculation
B30: Years | D30: 2020 | E30: =D30+1 -> 2021 | F30: =E30+1 -> 2022 | G30: =F30+1 -> 2023 | H30: =G30+1 -> 2024 | I30: =H30+1 -> 2025 | J30: =I30+1 -> 2026 | K30: =J30+1 -> 2027 | L30: =K30+1 -> 2028 | ... R30: =Q30+1 -> 2034
B32: EBIT | D32: ='Financial Statements'!C25 -> 819.986 | E32: ='Financial Statements'!D25 -> 1333.355 | F32: ='Financial Statements'!E25 -> 1328.408 | G32: ='Financial Statements'!F25 -> 2132.676 | H32: ='Financial Statements'!G25 -> 2505.697 | I32: ='Financial Statements'!H25 -> 2026.2487 | J32: ='Financial Statements'!I25 -> 2283.0781 | K32: ='Financial Statements'!J25 -> 2523.5006 | ... R32: ='Financial Statements'!Q25 -> 3340.4024
B33: Times: (1 - Tax Rate) | D33: =(1-'Supporting Schedules'!D27) -> 0.71875633 | E33: =(1-'Supporting Schedules'!E27) -> 0.73119774 | F33: =(1-'Supporting Schedules'!F27) -> 0.64146676 | G33: =(1-'Supporting Schedules'!G27) -> 0.71249026 | H33: =(1-'Supporting Schedules'!H27) -> 0.70441062 | I33: =(1-'Supporting Schedules'!I27) -> 0.697 | J33: =(1-'Supporting Schedules'!J27) -> 0.697 | K33: =(1-'Supporting Schedules'!K27) -> 0.697 | ... R33: =(1-'Supporting Schedules'!R27) -> 0.697
B34: Equals: NOPAT | D34: =D32*D33 -> 589.37013 | E34: =E32*E33 -> 974.94616 | F34: =F32*F33 -> 852.12957 | G34: =G32*G33 -> 1519.5109 | H34: =H32*H33 -> 1765.0396 | I34: =I32*I33 -> 1412.2954 | J34: =J32*J33 -> 1591.3054 | K34: =K32*K33 -> 1758.8799 | ... R34: =R32*R33 -> 2328.2604
B35: Plus: Depreciation & Amortization | D35: ='Financial Statements'!C38 -> 185.478 | E35: ='Financial Statements'!D38 -> 224.206 | F35: ='Financial Statements'!E38 -> 291.791 | G35: ='Financial Statements'!F38 -> 379.384 | H35: ='Financial Statements'!G38 -> 446.524 | I35: ='Financial Statements'!H38 -> 523.5014 | J35: ='Financial Statements'!I38 -> 601.53501 | K35: ='Financial Statements'!J38 -> 685.98615 | ... R35: ='Financial Statements'!Q38 -> 1184.2477
B36: Plus: Change In Working Capital | D36: =SUM('Financial Statements'!C121:C132) -> -47.549 | E36: =SUM('Financial Statements'!D121:D132) -> 129.131 | F36: =SUM('Financial Statements'!E121:E132) -> -659.92 | G36: =SUM('Financial Statements'!F121:F132) -> 199.223 | H36: =SUM('Financial Statements'!G121:G132) -> -51.895 | I36: ='Supporting Schedules'!I65 -> 112.93313 | J36: ='Supporting Schedules'!J65 -> -65.149945 | K36: ='Supporting Schedules'!K65 -> -60.835868 | L36: ='Supporting Schedules'!L65 -> -54.383159 | M36: ='Supporting Schedules'!M65 -> -46.936233 | N36: ='Supporting Schedules'!N65 -> -38.485613 | O36: ='Supporting Schedules'!O65 -> -28.851031 | P36: ='Supporting Schedules'!P65 -> -20.057816 | ... R36: ='Supporting Schedules'!R65 -> -64.215052
B37: Plus: Non Cash Expenses | D37: ='Supporting Schedules'!D95 -> 50.797 | E37: ='Supporting Schedules'!E95 -> 69.137 | F37: ='Supporting Schedules'!F95 -> 78.075 | G37: ='Supporting Schedules'!G95 -> 93.56 | H37: ='Supporting Schedules'!H95 -> 90.011 | I37: ='Supporting Schedules'!I95 -> 119.53361 | J37: ='Supporting Schedules'!J95 -> 134.66421 | K37: ='Supporting Schedules'!K95 -> 148.82823 | ... R37: ='Supporting Schedules'!R95 -> 196.9544
B38: Less: Capital Expenditures | D38: =-'Supporting Schedules'!D78 -> -259.472 | E38: =-'Supporting Schedules'!E78 -> -406.229 | F38: =-'Supporting Schedules'!F78 -> -633.695 | G38: =-'Supporting Schedules'!G78 -> -655.581 | H38: =-'Supporting Schedules'!H78 -> -681.33 | I38: =-'Supporting Schedules'!I78 -> -788.92183 | J38: =-'Supporting Schedules'!J78 -> -888.78379 | K38: =-'Supporting Schedules'!K78 -> -982.26632 | ... R38: =-'Supporting Schedules'!R78 -> -1299.8991
B39: Equals: Unlevered Free Cash Flow | D39: =SUM(D34:D38) -> 518.62413 | E39: =SUM(E34:E38) -> 991.19116 | F39: =SUM(F34:F38) -> -71.619426 | G39: =SUM(G34:G38) -> 1536.0969 | H39: =SUM(H34:H38) -> 1568.3496 | I39: =SUM(I34:I38) -> 1379.3417 | J39: =SUM(J34:J38) -> 1373.5709 | K39: =SUM(K34:K38) -> 1550.5921 | ... R39: =SUM(R34:R38) -> 2345.3484
B40: Times: Discount Period | I40: =(1-wacc)^I41 -> 0.89954495 | J40: =(1-wacc)^J41 -> 0.80918112 | K40: =(1-wacc)^K41 -> 0.72789479 | L40: =(1-wacc)^L41 -> 0.65477409 | M40: =(1-wacc)^M41 -> 0.58899872 | N40: =(1-wacc)^N41 -> 0.52983083 | O40: =(1-wacc)^O41 -> 0.47660665 | P40: =(1-wacc)^P41 -> 0.4287291 | ... R40: =(1-wacc)^R41 -> 0.3469195
B41: Discount Year | I41: 1 | J41: =I41+1 -> 2 | K41: =J41+1 -> 3 | L41: =K41+1 -> 4 | M41: =L41+1 -> 5 | N41: =M41+1 -> 6 | O41: =N41+1 -> 7 | P41: =O41+1 -> 8 | Q41: =P41+1 -> 9 | R41: =Q41+1 -> 10
B42: Equals: Present Value of Unlevered Free Cash Flow | D42: =D39*D40 -> 0 | E42: =E39*E40 -> 0 | F42: =F39*F40 -> 0 | G42: =G39*G40 -> 0 | H42: =H39*H40 -> 0 | I42: =I39*I40 -> 1240.7798 | J42: =J39*J40 -> 1111.4676 | K42: =K39*K40 -> 1128.6679 | ... R42: =R39*R40 -> 813.64709
B45: Discounted Cash Flow Valuation
B47: Perpetuity Growth Method | H47: WACC
B48: Perpetuity Growth Rate | D48: 0.02 | G48: =D59 -> 362.18832 | H48: =I48+0.01 -> 0.12045505 | I48: =J48+0.01 -> 0.11045505 | J48: 0.10045505 | K48: =J48-0.01 -> 0.090455048 | L48: =K48-0.01 -> 0.080455048
B49: Present Value of Terminal Value | D49: =IFERROR(R39*(1+tgr)/(wacc-tgr)," ") -> 29734.062 | F49: Perpetuity Growth Rate | G49: =G50+0.005 -> 0.03 | H49: 325.07275 | I49: 359.56251 | J49: 402.77281 | K49: 458.89291 | L49: 535.4176
B50: Terminal Value as % of Enterprise Value | D50: =IFERROR(D49/D53,0) -> 0.73918308 | G50: =G51+0.005 -> 0.025 | H50: 311.50881 | I50: 342.68015 | J50: 381.13591 | K50: 430.08875 | L50: 495.05452
B51: Plus: Present Value of Forecast FCF | D51: =SUM(D42:R42) -> 10491.51 | G51: 0.02 | H51: 299.29512 | I51: 327.66417 | J51: 362.18832 | K51: 405.37288 | L51: 461.36799
...

Sheet Comparables
B1: Sauder Capital Markets Challenge
B2: =company -> lululemon athletica inc.
B3: Financial Model
B4: Comparable Companies Analysis
B6: Current Share Price (USD) | C6: 212.54
B7: Diluted Shares Outstanding (m) | C7: 112.19
B8: Equity Value | C8: 24513.4
B9: Cash & Short Term Investments | C9: 1035.9
B10: Total Debt | C10: 1762.8
B11: Net Debt | C11: 726.9
B12: Enterprise Value | C12: 25240.3
B15: Comparable Companies: Peer Universe
B17: (All figures in USDm unless otherwise specified) | H17: EBITDA | K17: EV/EBITDA | O17: Price / Earnings
B18: Company Name | C18: Year End | D18: Ticker | E18: Price (USD) | F18: Market Cap | G18: Enterprise Value | H18: 2024A EBITDA | I18: 2025E EBITDA | J18: 2026E EBITDA | K18: 2024A EV/EBITDA | L18: 2025E EV/EBITDA | M18: 2026E EV/EBITDA | O18: 2024A Diluted EPS | P18: 2025E Diluted EPS | Q18: 2026E Diluted EPS | R18: 2024A P/E | S18: 2025E P/E | T18: 2026E P/E
B19: V.F Corporation | C19: 45927 | D19: NYSE: VFC | E19: 18.17 | F19: 7009.5 | G19: 12471.5 | H19: 809.9 | I19: 815.77 | J19: 862.13 | K19: =$G19/H19 -> 15.398815 | L19: =$G19/I19 -> 15.28801 | M19: =$G19/J19 -> 14.465916 | O19: 0.74 | P19: 0.74 | Q19: 0.73 | R19: =$E19/O19 -> 24.554054 | S19: =$E19/P19 -> 24.554054 | T19: =$E19/Q19 -> 24.890411
B20: Tapestry, Inc. | C20: 45927 | D20: NYSE: TPR | E20: 129.53 | F20: 26674 | G20: 30130.1 | H20: 1430.3 | I20: 1571.2 | J20: 1643.7 | K20: =$G20/H20 -> 21.065581 | L20: =$G20/I20 -> 19.176489 | M20: =$G20/J20 -> 18.330656 | O20: 4.29 | P20: 5.1 | Q20: 5.6 | R20: =$E20/O20 -> 30.193473 | S20: =$E20/P20 -> 25.398039 | T20: =$E20/Q20 -> 23.130357
B21: Ralph Lauren Corporation | C21: 45927 | D21: NYSE: RL | E21: 356.89 | F21: 21642 | G21: 22868.7 | H21: 1024.9 | I21: 1209.5 | J21: 1423.35 | K21: =$G21/H21 -> 22.313104 | L21: =$G21/I21 -> 18.907565 | M21: =$G21/J21 -> 16.066814 | O21: 10.31 | P21: 12.33 | Q21: 15.38 | R21: =$E21/O21 -> 34.615907 | S21: =$E21/P21 -> 28.94485 | T21: =$E21/Q21 -> 23.204811
B22: Gildan Activewear Inc. | C22: 45928 | D22: TSX: GIL | E22: 62.71 | F22: 9356.8 | G22: 11039.8 | H22: 814.5 | I22: 853.4 | J22: 909.63 | K22: =$G22/H22 -> 13.554082 | L22: =$G22/I22 -> 12.936255 | M22: =$G22/J22 -> 12.136583 | O22: 3 | P22: 3.48 | Q22: 4.52 | R22: =$E22/O22 -> 20.903333 | S22: =$E22/P22 -> 18.020115 | T22: =$E22/Q22 -> 13.873894
B23: PVH Corp. | C23: 45963 | D23: NYSE: PVH | E23: 68.22 | F23: 3124.7 | G23: 7226.5 | H23: 1216.5 | I23: 1147.4 | J23: 1040.49 | K23: =$G23/H23 -> 5.9404028 | L23: =$G23/I23 -> 6.2981523 | M23: =$G23/J23 -> 6.9452854 | O23: 10.68 | P23: 11.74 | Q23: 10.9 | R23: =$E23/O23 -> 6.3876404 | S23: =$E23/P23 -> 5.8109029 | T23: =$E23/Q23 -> 6.2587156
B24: Levi Strauss & Co. | C24: 45900 | D24: NYSE: LEVI | E24: 21.09 | F24: 8242.6 | G24: 9831.8 | H24: 846.4 | I24: 920.83 | J24: 1007.76 | K24: =$G24/H24 -> 11.616021 | L24: =$G24/I24 -> 10.677107 | M24: =$G24/J24 -> 9.7560927 | O24: 1.25 | P24: 1.33 | Q24: 1.47 | R24: =$E24/O24 -> 16.872 | S24: =$E24/P24 -> 15.857143 | T24: =$E24/Q24 -> 14.346939
B27: Minimum | K27: =IFERROR(MIN(K$19:K25),"") -> 5.9404028 | L27: =IFERROR(MIN(L$19:L25),"") -> 6.2981523 | M27: =IFERROR(MIN(M$19:M25),"") -> 6.9452854 | R27: =IFERROR(MIN(R$19:R25),"") -> 6.3876404 | S27: =IFERROR(MIN(S$19:S25),"") -> 5.8109029 | T27: =IFERROR(MIN(T$19:T25),"") -> 6.2587156
B28: Median | K28: =IFERROR(MEDIAN(K19:K25),"") -> 14.476448 | L28: =IFERROR(MEDIAN(L19:L25),"") -> 14.112133 | M28: =IFERROR(MEDIAN(M19:M25),"") -> 13.301249 | R28: =IFERROR(MEDIAN(R19:R25),"") -> 22.728694 | S28: =IFERROR(MEDIAN(S19:S25),"") -> 21.287084 | T28: =IFERROR(MEDIAN(T19:T25),"") -> 18.738648
B29: Mean | K29: =IFERROR(AVERAGE(K19:K25),"") -> 14.981334 | L29: =IFERROR(AVERAGE(L19:L25),"") -> 13.880596 | M29: =IFERROR(AVERAGE(M19:M25),"") -> 12.950225 | R29: =IFERROR(AVERAGE(R19:R25),"") -> 22.254401 | S29: =IFERROR(AVERAGE(S19:S25),"") -> 19.764184 | T29: =IFERROR(AVERAGE(T19:T25),"") -> 17.617521
B30: Maximum | K30: =IFERROR(MAX(K19:K24),"") -> 22.313104 | L30: =IFERROR(MAX(L19:L24),"") -> 19.176489 | M30: =IFERROR(MAX(M19:M24),"") -> 18.330656 | R30: =IFERROR(MAX(R19:R24),"") -> 34.615907 | S30: =IFERROR(MAX(S19:S24),"") -> 28.94485 | T30: =IFERROR(MAX(T19:T24),"") -> 24.890411
B32: lululemon athletica inc. | C32: 46022 | D32: NASDAQ: LULU | E32: 212.54 | F32: 24513.4 | G32: 25240.3 | H32: 2261.14 | I32: 2952.22 | J32: 2690.27 | K32: =$G32/H32 -> 11.162644 | L32: =$G32/I32 -> 8.5496 | M32: =$G32/J32 -> 9.3820695 | O32: 14.64 | P32: 13.02 | Q32: 12.63 | R32: =$E32/O32 -> 14.51776 | S32: =$E32/P32 -> 16.324117 | T32: =$E32/Q32 -> 16.828187
B35: Comparable Companies Valuation
D37: Multiple | G37: Implied Equity Value | J37: Implied Share Price (USD) | M37: Implied Return (%)
B38: Metric | D38: Lower Limit | E38: Median | F38: Upper Limit | G38: Lower Limit | H38: Median | I38: Upper Limit | J38: Lower Limit | K38: Median | L38: Upper Limit | M38: Lower Limit | N38: Median | O38: Upper Limit
B39: EV/EBITDA 2024A | D39: =K27 -> 5.9404028 | E39: =K28 -> 14.476448 | F39: =K30 -> 22.313104 | G39: =($H$32*D39)-C11 -> 12705.182 | H39: =($H$32*E39)-D11 -> 32733.277 | I39: =($H$32*F39)-E11 -> 50453.051 | J39: =IFERROR(G39/dilutedshares,"") -> 113.24701 | K39: =IFERROR(H39/dilutedshares,"") -> 291.76644 | L39: =IFERROR(I39/dilutedshares,"") -> 449.71077 | M39: =IFERROR((J39/currentprice)-1,"") -> -0.46717318 | N39: =IFERROR((K39/currentprice)-1,"") -> 0.37276013 | O39: =IFERROR((L39/currentprice)-1,"") -> 1.1158877
B40: EV/EBITDA 2025E | D40: =L27 -> 6.2981523 | E40: =L28 -> 14.112133 | F40: =L30 -> 19.176489 | G40: =($I$32*D40)-C11 -> 17866.631 | H40: =($I$32*E40)-D11 -> 41662.12 | I40: =($I$32*F40)-E11 -> 56613.215 | J40: =IFERROR(G40/dilutedshares,"") -> 159.25333 | K40: =IFERROR(H40/dilutedshares,"") -> 371.35324 | L40: =IFERROR(I40/dilutedshares,"") -> 504.61909 | M40: =IFERROR((J40/currentprice)-1,"") -> -0.2507136 | N40: =IFERROR((K40/currentprice)-1,"") -> 0.74721577 | O40: =IFERROR((L40/currentprice)-1,"") -> 1.3742311
B41: EV/EBITDA 2026E | D41: =M27 -> 6.9452854 | E41: =M28 -> 13.301249 | F41: =M30 -> 18.330656 | G41: =(J$32*D41)-C11 -> 17957.793 | H41: =(J$32*E41)-D11 -> 35783.952 | I41: =($J$32*F41)-E11 -> 49314.415 | J41: =IFERROR(G41/dilutedshares,"") -> 160.0659 | K41: =IFERROR(H41/dilutedshares,"") -> 318.95848 | L41: =IFERROR(I41/dilutedshares,"") -> 439.56159 | M41: =IFERROR((J41/currentprice)-1,"") -> -0.24689048 | N41: =IFERROR((K41/currentprice)-1,"") -> 0.50069861 | O41: =IFERROR((L41/currentprice)-1,"") -> 1.0681358
D43: Multiple | G43: Implied Equity Value | J43: Implied Share Price (USD) | M43: Implied Return (%)
B44: Metric | D44: Lower Limit | E44: Median | F44: Upper Limit | G44: Lower Limit | H44: Median | I44: Upper Limit | J44: Lower Limit | K44: Median | L44: Upper Limit | M44: Lower Limit | N44: Median | O44: Upper Limit
B45: P/E 2024A | D45: =R27 -> 6.3876404 | E45: =R28 -> 22.728694 | F45: =R30 -> 34.615907 | G45: =IFERROR((O32*D45*dilutedshares),"") -> 10491.454 | H45: =IFERROR((O32*E45*dilutedshares),"") -> 37331.007 | I45: =IFERROR((O32*F45*dilutedshares),"") -> 56855.298 | J45: =IFERROR(G45/dilutedshares,"") -> 93.515056 | K45: =IFERROR(H45/dilutedshares,"") -> 332.74808 | L45: =IFERROR(I45/dilutedshares,"") -> 506.77688 | M45: =IFERROR((J45/currentprice)-1,"") -> -0.56001197 | N45: =IFERROR((K45/currentprice)-1,"") -> 0.5655786 | O45: =IFERROR((L45/currentprice)-1,"") -> 1.3843835
B46: P/E 2025E | D46: =S27 -> 5.8109029 | E46: =S28 -> 21.287084 | F46: =S30 -> 28.94485 | G46: =IFERROR((P32*D46*dilutedshares),"") -> 8488.0661 | H46: =IFERROR((P32*E46*dilutedshares),"") -> 31094.338 | I46: =IFERROR((P32*F46*dilutedshares),"") -> 42280.142 | J46: =IFERROR(G46/dilutedshares,"") -> 75.657956 | K46: =IFERROR(H46/dilutedshares,"") -> 277.15784 | L46: =IFERROR(I46/dilutedshares,"") -> 376.86195 | M46: =IFERROR((J46/currentprice)-1,"") -> -0.64402957 | N46: =IFERROR((K46/currentprice)-1,"") -> 0.30402673 | O46: =IFERROR((L46/currentprice)-1,"") -> 0.77313422
B47: P/E 2026E | D47: =T27 -> 6.2587156 | E47: =T28 -> 18.738648 | F47: =T30 -> 24.890411 | G47: =IFERROR((Q32*D47*dilutedshares),"") -> 8868.3478 | H47: =IFERROR((Q32*E47*dilutedshares),"") -> 26551.909 | I47: =IFERROR((Q32*F47*dilutedshares),"") -> 35268.709 | J47: =IFERROR(G47/dilutedshares,"") -> 79.047578 | K47: =IFERROR(H47/dilutedshares,"") -> 236.66912 | L47: =IFERROR(I47/dilutedshares,"") -> 314.36589 | M47: =IFERROR((J47/currentprice)-1,"") -> -0.62808141 | N47: =IFERROR((K47/currentprice)-1,"") -> 0.11352745 | O47: =IFERROR((L47/currentprice)-1,"") -> 0.47909048

Sheet Precedents
B1: Sauder Capital Markets Challenge
B2: =company -> lululemon athletica inc.
B3: Financial Model
B4: Precedent Transaction Analysis
B6: Financial Data
B8: Current Share Price (USD) | C8: 212.54
B9: Diluted Shares Outstanding (m) | C9: 112.19
B10: Net Debt | C10: 1762.8
B12: LTM Revenue | C12: 11073.3
B13: LTM EBITDA | C13: 2935.8
B14: LTM Net Income | C14: 1740.7
B15: LTM EPS | C15: 14.5
B18: Precedents Transactions
B20: (All figures in USDm unless otherwise specified) | F20: LTM Multiples
B21: Acquirer | C21: Target | D21: Announcement Date | E21: Transaction Value | F21: TV / Revenue | G21: TV / EBITDA | H21: Offer Price / EPS | I21: Rationale
B22: Gildan Activewear Inc. | C22: HanesBrands Inc. | D22: 45882 | E22: 4745.35 | F22: 1.3436828 | G22: 9.3338906 | H22: 6.4516129 | I22: Gildan is buying Hanes to gain scale and cut costs, making it a clear apparel consolidation precedent.
B23: Authentic Brands Group, LLC | C23: Levi Strauss & Co. | D23: 45797 | E23: 280.25 | F23: 0.042530428 | G23: 0.292506 | I23: Authentic acquired Dockers from Levi Strauss to add a well-known casual apparel brand to its portfolio.
B24: Advent International, L.P | C24: lululemon athletica inc. | D24: 41858 | E24: 845 | F24: 0.47017583 | G24: 1.9742991 | H24: 25.325301 | I24: Advent invested to support lululemon’s global growth and operational scaling in premium activewear.
B25: Legion Partners Asset Management, LLC | C25: Perry Ellis International, Inc. | D25: 43137 | E25: 486.21 | F25: 0.55207222 | G25: 10.366951 | H25: 8.3586626 | I25: Legion Partners targeted Perry Ellis to improve performance across its branded clothing portfolio.
B26: P180 | C26: Vince Holding Corp. | D26: 45679 | E26: 169.85 | F26: 0.57870528 | G26: 15.165179 | I26: P180 acquired Vince to add a premium apparel brand and drive operational improvements.
B27: Pacific Dunlop Investments Inc. | C27: Lakeland Industries, Inc. | D27: 40900 | E27: 3.03 | F27: 0.031464174 | G27: 0.91818182 | H27: 16.666667 | I27: Pacific Dunlop acquired Lakeland to expand its safety apparel portfolio and gain exposure to protective clothing markets.
B30: Minimum | F30: =IFERROR(MIN(F22:F27), " ") -> 0.031464174 | G30: =IFERROR(MIN(G22:G27), " ") -> 0.292506 | H30: =IFERROR(MIN(H22:H27), " ") -> 6.4516129
B31: Median | F31: =IFERROR(MEDIAN(F$22:F$27), " ") -> 0.51112402 | G31: =IFERROR(MEDIAN(G$22:G$27), " ") -> 5.6540949 | H31: =IFERROR(MEDIAN(H$22:H$27), " ") -> 12.512665
B32: Mean | F32: =IFERROR(AVERAGE(F$22:F$27), " ") -> 0.50310511 | G32: =IFERROR(AVERAGE(G$22:G$27), " ") -> 6.3418345 | H32: =IFERROR(AVERAGE(H$22:H$27), " ") -> 14.200561
B33: Maximum | F33: =IFERROR(MAX(F$22:F$27), " ") -> 1.3436828 | G33: =IFERROR(MAX(G$22:G$27), " ") -> 15.165179 | H33: =IFERROR(MAX(H$22:H$27), " ") -> 25.325301
B36: Valuation
C38: LTM Multiples
C39: TV / Revenue | D39: TV / EBITDA | E39: Offer Price / EPS
B40: Transaction Value | C40: =$F$31*$C$12 -> 5659.8296 | D40: =$G$31*$C$13 -> 16599.292 | E40: =$H$31*$C$15*$C$9 -> 20355.04
B41: Less: Net Debt | C41: =-$C$10 -> -1762.8 | D41: =-$C$10 -> -1762.8 | E41: =0 -> 0
B42: Equals: Implied Equity Value | C42: =SUM(C40:C41) -> 3897.0296 | D42: =SUM(D40:D41) -> 14836.492 | E42: =SUM(E40:E41) -> 20355.04
B43: Implied Share Price | C43: =C42/C9 -> 34.73598 | D43: =D42/C9 -> 132.24433 | E43: =E42/C9 -> 181.43364
B44: Implied Return | C44: =C43/C8-1 -> -0.83656733 | D44: =D43/C8-1 -> -0.37779085 | E44: =E43/C8-1 -> -0.14635533
